Workbook
Name _Hlk138872368: 附註!$A$6

Sheet 資產負債表
A1: 鍍威精密股份有限公司
A2: 資 產 負 債 表
A3: 民國一一三年十二月三十一日及一一二年十二月三十一日
A4: 單位：新台幣元
N5: (未經查核)
C6: 一一三年十二月三十一日 | H6: 一一二年十二月三十一日 | N6: 一一一年十二月三十一日
C7: 金額 | F7: % | H7: 金額 | K7: % | N7: 金額 | Q7: %
A8: 資 產
A9: 流動資產
A10: 現金及約當現金(附註四(一)) | C10: $ | D10: =SUM(BS!C3:C9) -> 5408583 | F10: =ROUND(D10/D$25*100,1) -> 5.1 | H10: $ | I10: 7588579 | K10: =ROUND(I10/I$25*100,1)+0.1 -> 7.7 | N10: $ | O10: 20541058 | Q10: 18.6 | S10: =D10-I10 -> -2179996 | U10: =I10-O10 -> -12952479
A11: 應收票據(附註四(二)) | D11: =BS!C10 -> 4597726 | F11: =ROUND(D11/D$25*100,1) -> 4.4 | I11: 3205259 | K11: =ROUND(I11/I$25*100,1) -> 3.2 | O11: 1441674 | Q11: 1.3 | S11: =I11-D11 -> -1392467 | U11: =O11-I11 -> -1763585
A12: 應收帳款(附註四(三)) | D12: =BS!C11 -> 13444980 | F12: =ROUND(D12/D$25*100,1) -> 12.7 | I12: 7243970 | K12: =ROUND(I12/I$25*100,1) -> 7.2 | O12: 3176716 | Q12: 2.9 | S12: =I12-D12 -> -6201010 | U12: =O12-I12 -> -4067254
A13: 其他應收帳款(附註四(四)) | D13: =BS!C12 -> 1028274 | F13: =ROUND(D13/D$25*100,1) -> 1 | I13: 1197720 | K13: =ROUND(I13/I$25*100,1) -> 1.2 | O13: 1274000 | Q13: 1.2 | S13: =I13-D13 -> 169446 | U13: =O13-I13 -> 76280
A14: 存 貨(附註四(五)) | D14: =BS!C13 -> 2961265 | F14: =ROUND(D14/D$25*100,1) -> 2.8 | I14: 2450275 | K14: =ROUND(I14/I$25*100,1) -> 2.4 | O14: 2136413 | Q14: 1.9 | S14: =I14-D14 -> -510990 | U14: =O14-I14 -> -313862
A15: 預付款項(附註四(六)) | D15: =BS!C15 -> 395327 | F15: =ROUND(D15/D$25*100,1) -> 0.4 | I15: 1354094 | K15: =ROUND(I15/I$25*100,1) -> 1.4 | O15: 2128113 | Q15: 1.9 | S15: =I15-D15 -> 958767 | U15: =O15-I15 -> 774019
A16: 其他流動資產 | D16: =BS!C17 -> 288811 | F16: =ROUND(D16/D$25*100,1) -> 0.3 | I16: 23825 | K16: =ROUND(I16/I$25*100,1) -> 0 | O16: 1186596 | Q16: 1.2 | S16: =I16-D16 -> -264986 | U16: =O16-I16 -> 1162771
A17: 流動資產合計 | D17: =SUM($D$10:$D$16) -> 28124966 | F17: =SUM($F$10:$F$16) -> 26.7 | I17: =SUM($I$10:$I$16) -> 23063722 | K17: =SUM($K$10:$K$16) -> 23.1 | O17: 31884570 | Q17: 29
A18: 非流動資產
A19: 不動產、廠房及設備(附註四(七)) | D19: =BS!C21 -> 54440717 | F19: =ROUND(D19/D$25*100,1) -> 51.6 | I19: 55901057 | K19: =ROUND(I19/I$25*100,1) -> 55.7 | O19: 58976404 | Q19: 53.5 | S19: =I19-D19 -> 1460340 | T19: 折舊 | U19: =O19-I19 -> 3075347
A20: 無形資產(附註四(八)) | D20: =BS!C32+BS!C33 -> 244718 | F20: =ROUND(D20/D$25*100,1) -> 0.2 | I20: 120347 | K20: =ROUND(I20/I$25*100,1) -> 0.1 | O20: 221615 | Q20: 0.2
A21: 存出保證金(附註四(九)) | D21: =BS!C35 -> 16825600 | F21: =ROUND(D21/D$25*100,1) -> 15.9 | I21: 16825600 | K21: =ROUND(I21/I$25*100,1) -> 16.8 | O21: 16810600 | Q21: 15.2 | S21: =I21-D21 -> 0 | U21: =O21-I21 -> -15000
A22: 預付設備款(附註四(十)) | D22: =BS!C36 -> 1596848 | F22: =ROUND(D22/D$25*100,1) -> 1.5 | I22: 0 | K22: 0
A23: 遞延所得稅資產(附註四(十八)) | D23: =BS!C37 -> 4314920 | F23: =ROUND(D23/D$25*100,1) -> 4.1 | I23: 4361682 | K23: =ROUND(I23/I$25*100,1) -> 4.3 | O23: 2361682 | Q23: 2.1 | S23: =I23-D23 -> 46762 | U23: =O23-I23 -> -2000000
A24: 非流動資產合計 | D24: =SUM(D19:D23) -> 77422803 | F24: =SUM(F19:F23) -> 73.3 | I24: =SUM(I19:I23) -> 77208686 | K24: =SUM(K19:K23) -> 76.9 | O24: 78370301 | Q24: 71
A25: 資 產 總 計 | C25: $ | D25: =$D$17+$D$24 -> 105547769 | F25: =$F$17+$F$24 -> 100 | H25: $ | I25: =$I$17+$I$24 -> 100272408 | K25: =$K$17+$K$24 -> 100 | N25: $ | O25: 110254871 | Q25: 100
A27: 負 債 及 權 益
A28: 流動負債
A29: 應付票據(附註四(十一)) | C29: $ | D29: =BS!G5 -> 311654 | F29: =ROUND(D29/D$25*100,1) -> 0.3 | H29: $ | I29: 2455819 | K29: =ROUND(I29/I$25*100,1) -> 2.4 | O29: 11960991 | Q29: 10.8 | S29: =D29-I29 -> -2144165 | U29: =I29-O29 -> -9505172
A30: 應付帳款(附註四(十二)) | D30: =BS!G6 -> 4339539 | F30: =ROUND(D30/D$25*100,1) -> 4.1 | I30: 5966576 | K30: =ROUND(I30/I$25*100,1)-0.1 -> 5.9 | N30: $ | O30: 3459200 | Q30: 3.1 | S30: =D30-I30 -> -1627037 | U30: =I30-O30 -> 2507376
A31: 其他應付款(附註四(十三)) | D31: =BS!G7 -> 11112008 | F31: =ROUND(D31/D$25*100,1) -> 10.5 | I31: 8603814 | K31: =ROUND(I31/I$25*100,1) -> 8.6 | O31: 8369093 | Q31: 7.6 | S31: =D31-I31 -> 2508194 | U31: =I31-O31 -> 234721
A32: 預收貨款 | D32: 1202 | F32: =ROUND(D32/D$25*100,1) -> 0 | I32: 0 | K32: 0 | S32: =D32-I32 -> 1202 | U32: =I32-O32 -> 0
A33: 其他流動負債(附註四(十三)) | D33: =BS!G14 -> 207418 | F33: =ROUND(D33/D$25*100,1) -> 0.2 | I33: 153246 | K33: =ROUND(I33/I$25*100,1) -> 0.2 | O33: 111363 | Q33: 0.1 | S33: =D33-I33 -> 54172 | U33: =I33-O33 -> 41883
A34: 一年內到期長期借款(附註四(十四)) | D34: =BS!G3 -> 6701448 | F34: =ROUND(D34/D$25*100,1) -> 6.3 | I34: 2594200 | K34: =ROUND(I34/I$25*100,1) -> 2.6 | O34: 2979507 | Q34: 2.7 | S34: =D34-I34 -> 4107248 | U34: =I34-O34 -> -385307
A35: 流動負債合計 | D35: =SUM(D29:D34) -> 22673269 | F35: =SUM(F29:F34) -> 21.4 | I35: =SUM(I29:I34) -> 19773655 | K35: =SUM(K29:K34) -> 19.7 | O35: 26880154 | Q35: 24.3
A36: 非流動負債
A37: 長期借款(附註四(十四)) | D37: =BS!G17 -> 21601165 | F37: =ROUND(D37/D$25*100,1) -> 20.5 | I37: 19412464 | K37: =ROUND(I37/I$25*100,1)-0.1 -> 19.3 | O37: 11421445 | Q37: 10.4 | S37: =D37-I37 -> 2188701 | U37: =I37-O37 -> 7991019
A38: 非流動負債合計 | D38: =SUM(D37:D37) -> 21601165 | F38: =SUM(F37:F37) -> 20.5 | I38: =SUM(I37:I37) -> 19412464 | K38: =SUM(K37:K37) -> 19.3 | O38: 11421445 | Q38: 10.4
A39: 負債總計 | D39: =D35+D38 -> 44274434 | F39: =F35+F38 -> 41.9 | I39: =I35+I38 -> 39186119 | K39: =K35+K38 -> 39 | O39: 38301599 | Q39: 34.7
A41: 權 益
A42: 股 本(附註四(十五)) | D42: =BS!H20 -> 90000000 | F42: =ROUND(D42/D$25*100,1) -> 85.3 | I42: 90000000 | K42: =ROUND(I42/I$25*100,1) -> 89.8 | O42: 80000000 | Q42: 72.6 | S42: =D42-I42 -> 0 | U42: =I42-O42 -> 10000000
...

Sheet 損益表
A1: =資產負債表!A1 -> 鍍威精密股份有限公司
A2: 綜 合 損 益 表
A3: 民國一一三年一月一日至十二月三十一日
A4: 及一一二年一月一日至十二月三十一日
A6: 單位：新台幣元
C7: 一一三年度 | H7: 一一二年度
A9: 項目 | C9: 金額 | F9: % | H9: 金額 | K9: %
A10: 營業收入 | C10: $ | D10: =IS!D6 -> 52599315 | F10: =D10/D$10*100 -> 100 | H10: $ | I10: 28721719 | K10: =I10/I$10*100 -> 100
A11: 營業成本(附註四(十九)) | D11: =-IS!D7 -> -33039914 | F11: =ROUND(D11/D$10*100,2) -> -62.81 | I11: -34288954 | K11: =ROUND(I11/I$10*100,2) -> -119.38
A12: 營業毛利(損) | D12: =D10+D11 -> 19559401 | F12: =F10+F11 -> 37.19 | I12: =I10+I11 -> -5567235 | K12: =K10+K11 -> -19.38
A13: 營業費用 | D13: =-IS!D43 -> -19136173 | F13: =ROUND(D13/D$10*100,2) -> -36.38 | I13: -16891577 | K13: =ROUND(I13/I$10*100,2) -> -58.81
A14: 營業淨利(損) | D14: =D12+D13 -> 423228 | F14: =F12+F13 -> 0.81 | I14: =I12+I13 -> -22458812 | K14: =K12+K13 -> -78.19
A15: 營業外收益及費損
A16: 利息收入 | D16: =IS!C67 -> 160806 | F16: =ROUND(D16/D$10*100,2) -> 0.31 | I16: 185761 | K16: =ROUND(I16/I$10*100,2) -> 0.65
A17: 租金收入
A18: 股利收入
A19: 利息費用
A20: 採用權益法認列之投資損益
A21: 利息費用 | D21: =-IS!C71 -> -704142 | F21: =ROUND(D21/D$10*100,2) -> -1.34 | I21: -372259 | K21: =ROUND(I21/I$10*100,2) -> -1.3
A22: 處分投資損益 | D22: 0 | F22: =ROUND(D22/D$10*100,2) -> 0 | I22: 0 | K22: =ROUND(I22/I$10*100,2) -> 0
A23: 處分不動產、廠房及設備損益 | D23: 0 | F23: =ROUND(D23/D$10*100,2) -> 0 | I23: 0 | K23: =ROUND(I23/I$10*100,2) -> 0
A24: 其他營業外收益及費損 | D24: =IS!C68+IS!C69 -> 353916 | F24: =ROUND(D24/D$10*100,2) -> 0.67 | I24: -221673 | K24: =ROUND(I24/I$10*100,2) -> -0.77
A25: 營業外收益及費損合計 | D25: =SUM(D16:D24) -> -189420 | F25: =SUM(F16:F24) -> -0.36 | I25: =SUM(I16:I24) -> -408171 | K25: =SUM(K16:K24) -> -1.42
A26: 稅前淨利(損) | D26: =D14+D25 -> 233808 | F26: =F14+F25 -> 0.45 | I26: =I14+I25 -> -22866983 | K26: =K14+K25 -> -79.61
A27: 所得稅利益(費用)(附註四(十八)) | D27: =-IS!C73 -> -46762 | F27: =ROUND(D27/D$10*100,2) -> -0.09 | I27: 2000000 | K27: =ROUND(I27/I$10*100,2) -> 6.96
A28: 本期稅後淨損 | D28: =D26+D27 -> 187046 | F28: =F26+F27 -> 0.36 | I28: =I26+I27 -> -20866983 | K28: =K26+K27 -> -72.65
A29: 本期其他綜合損益 | D29: 0 | F29: 0 | I29: 0 | K29: 0
A30: 本期綜合損益總額 | C30: $ | D30: =D28 -> 187046 | F30: =F28 -> 0.36 | H30: $ | I30: =I28 -> -20866983 | K30: =K28 -> -72.65
A31: (請參閱後附財務報表附註)
A33: 負 責 人： | D33: 經理人： | I33: 主辦會計：

Sheet 股東變動表
A1: =損益表!A1 -> 鍍威精密股份有限公司
A2: 權 益 變 動 表
A3: =損益表!A3 -> 民國一一三年一月一日至十二月三十一日
A4: =損益表!A4 -> 及一一二年一月一日至十二月三十一日
A5: 單位：新台幣元
I6: 保留盈餘
C7: 股本 | F7: 資本公積 | I7: 法定盈餘 公積 | L7: 未分配盈餘 | O7: 權益總計
A8: 一一二年一月一日餘額 | C8: $ | D8: 80000000 | F8: $ | G8: 1400000 | I8: $ | J8: 0 | L8: $ | M8: -9446728 | O8: $ | P8: 71953272
A9: 現金增資(附註四(十五)) | D9: 10000000 | G9: 0 | J9: 0 | M9: 0 | P9: 10000000
A10: 盈餘指撥及分配
A11: 法定盈餘公積 | D11: 0 | G11: 0 | J11: 0 | M11: 0 | P11: 0
A12: 現金股利 | D12: 0 | G12: 0 | J12: 0 | P12: 0
A13: 本期稅後淨損 | D13: 0 | G13: 0 | J13: 0 | M13: =損益表!I28 -> -20866983 | P13: =M13 -> -20866983
A14: 一一二年十二月三十一日餘額 | C14: $ | D14: 90000000 | F14: $ | G14: 1400000 | I14: $ | J14: 0 | L14: $ | M14: =SUM(M8:M13) -> -30313711 | O14: $ | P14: =SUM(P8:P13) -> 61086289
A15: 一一三年一月一日餘額 | C15: $ | D15: =D14 -> 90000000 | F15: $ | G15: =G14 -> 1400000 | I15: $ | J15: 0 | L15: $ | M15: =M14 -> -30313711 | O15: $ | P15: =SUM(D15:N15) -> 61086289
A16: 現金增資(附註四(十五)) | D16: 0 | G16: 0 | J16: 0 | M16: 0 | P16: =SUM(D16:N16) -> 0
A17: 盈餘指撥及分配
A18: 法定盈餘公積 | D18: 0 | G18: 0 | J18: 0 | M18: 0 | P18: =SUM(D18:N18) -> 0
A19: 現金股利 | D19: 0 | G19: 0 | J19: 0 | P19: =SUM(D19:N19) -> 0
A20: 本期稅後淨利 | D20: 0 | G20: 0 | J20: 0 | M20: =損益表!D28 -> 187046 | P20: =SUM(D20:N20) -> 187046
A21: 一一三年十二月三十一日餘額 | C21: $ | D21: =SUM(D15:D20) -> 90000000 | F21: $ | G21: =SUM(G15:G20) -> 1400000 | I21: $ | J21: =SUM(J15:J20) -> 0 | L21: $ | M21: =M15-M19+M20 -> -30126665 | O21: $ | P21: =P15-P19+P20+P16 -> 61273335
A24: (請參閱後附財務報表附註)
A27: 負 責 人： | F27: 經理人： | M27: 主辦會計：

Sheet 現金流量表
A1: =資產負債表!A1 -> 鍍威精密股份有限公司
A2: 現金流量表
A3: =損益表!A3 -> 民國一一三年一月一日至十二月三十一日
A4: =損益表!A4 -> 及一一二年一月一日至十二月三十一日
A6: 單位：新台幣元
C7: =損益表!C7 -> 一一三年度 | H7: 一一二年度
A9: 營業活動之現金流量
A10: 本期稅前淨利(損) | C10: $ | D10: =損益表!D26 -> 233808 | H10: $ | I10: =損益表!I26 -> -22866983
A11: 調整項目：
A12: 收益費損項目
A13: 利息收入 | D13: =-損益表!D16 -> -160806 | I13: =-損益表!I16 -> -185761
A14: 利息費用 | D14: =-損益表!D21 -> 704142 | I14: =-損益表!I21 -> 372259
A15: 折舊費用 | D15: =-'調節表 '!D53 -> 3848594 | I15: =-'調節表 '!E53 -> 7976172
A16: 攤銷費用 | D16: =-'調節表 '!D84 -> 51107 | I16: =-'調節表 '!E84 -> 101268
A17: 處分不動產、廠房及設備損益
A18: 與營業活動相關之流動資產/負債變動數
A19: 應收票據增加 | D19: =資產負債表!S11 -> -1392467 | I19: =資產負債表!U11 -> -1763585
A20: 應收帳款增加 | D20: =資產負債表!S12 -> -6201010 | I20: =資產負債表!U12 -> -4067254
A21: 其他應收款減少 | D21: =資產負債表!S13 -> 169446 | I21: =資產負債表!U13 -> 76280
A22: 存貨增加 | D22: =資產負債表!S14 -> -510990 | I22: =資產負債表!U14 -> -313862
A23: 預付款項減少 | D23: =資產負債表!S15 -> 958767 | I23: =資產負債表!U15 -> 774019
A24: 其他流動資產(增加)減少 | D24: =資產負債表!S16 -> -264986 | I24: =資產負債表!U16 -> 1162771
A25: 應付票據減少 | D25: =資產負債表!S29 -> -2144165 | I25: =資產負債表!U29 -> -9505172
A26: 應付帳款(減少)增加 | D26: =資產負債表!S30 -> -1627037 | I26: =資產負債表!U30 -> 2507376
A27: 其他應付款增加 | D27: ='調節表 '!D5 -> 2493008 | I27: ='調節表 '!E5 -> 231030
A28: 預收款項增加 | D28: =資產負債表!S32 -> 1202 | I28: 0
A29: 其他流動負債增加 | D29: =資產負債表!S33 -> 54172 | I29: =資產負債表!I33-資產負債表!O33 -> 41883
A30: 營運產生之現金 | D30: =SUM(D10:D29) -> -3787215 | I30: =SUM(I10:I29) -> -25459559
A31: 支付之利息 | D31: =-'調節表 '!D11 -> -688956 | I31: =-'調節表 '!E11 -> -368568
A32: 支付之所得稅 | D32: 0 | I32: 0
A33: 收取之利息 | D33: =損益表!D16 -> 160806 | I33: =損益表!I16 -> 185761
A34: 收取之股利
A35: 營業活動之淨現金流出 | D35: =SUM(D30:D33) -> -4315365 | I35: =SUM(I30:I33) -> -25642366
A37: 投資活動之現金流量
A38: 取得不動產、廠房及設備 | D38: =-'調節表 '!D50 -> -2388254 | I38: =-'調節表 '!E50 -> -4900825
A39: 處分不動產、廠房及設備價款
A40: 取得無形資產 | D40: =-'調節表 '!D83 -> -175478 | I40: 0
A41: 預付設備款增加 | D41: =-'調節表 '!D79 -> -1596848 | I41: 0
A42: 存出保證金增加 | D42: =資產負債表!S21 -> 0 | I42: =資產負債表!U21 -> -15000
A43: 投資活動之淨現金流出 | D43: =SUM(D38:D42) -> -4160580 | I43: =SUM(I38:I42) -> -4915825
...

Sheet 調節表 
A2: 1 | D2: 113年度 | E2: 112年度
B3: 期初應付費用 | D3: =E4 -> 8592311 | E3: 8361281
B4: 期末應付費用 | D4: =BS!G7-D10 -> 11085319 | E4: 8592311
B5: 應付費用付現數 | C5: A | D5: =D4-D3 -> 2493008 | E5: =E4-E3 -> 231030
D7: =$D$13 -> 113年度 | E7: =$E$13 -> 112年度
A8: 2 | B8: 期初應付利息 | D8: =E10 -> 11503 | E8: 7812
B9: 本期利息費用 | C9: D | D9: =-損益表!D21 -> 704142 | E9: 372259
B10: 期末應付利息 | D10: 26689 | E10: 11503
B11: 利息付現數 | C11: E | D11: =D8+D9-D10 -> 688956 | E11: =E8+E9-E10 -> 368568
D13: =D2 -> 113年度 | E13: =E2 -> 112年度 | H13: 支付所得稅 | I13: 111 | J13: 110 | K13: 109 | L13: 108
A14: 3 | B14: 期初應付所得稅 | D14: =E18 -> 0 | E14: 0 | H14: 暫繳
B15: 期初應退所得稅 | D15: =E19 -> 0 | E15: 0
B16: 期初遞延所得稅負債 | E16: 0 | H16: 未分配
B17: 本期所得稅費用 | C17: B | D17: 0 | E17: 0 | H17: 補稅
B18: 期末應付所得稅 | D18: 0 | E18: 0 | H18: 108營所
B19: 期末應退所得稅 | D19: 0 | E19: 0
B20: 本期支付所得稅 | C20: C | D20: =D14-D15+D17-D18+D19 -> 0 | E20: 0 | H20: 收到所得稅
H21: 淨支付 | I21: =I19-I20 -> 0 | J21: =J19-J20 -> 0
D22: =D7 -> 113年度 | E22: =E7 -> 112年度
B23: 期初其他應付款
B24: 期初應付利息
B25: 期初小計
B26: 期末其他應付款
B27: 期末應付利息
B28: 期末小計
B29: 本期變動數 | C29: h.
D31: =D22 -> 113年度 | E31: =E22 -> 112年度
B32: 期初其他流動資產
B33: 期初應收利息
B34: 期初小計
B35: 期末其他流動資產
B36: 期末應收利息
B37: 期末小計
B38: 本期變動數 | C38: e.
D40: =D31 -> 113年度 | E40: =E31 -> 112年度
B41: 期初無形資產 | D41: =D21 -> 0
B42: 預付未攤銷費用重分類
B43: 本期增添
B44: 利息資本化
B45: 攤提費用
...

Sheet 附註
A1: (一)現金及約當現金
C2: 一一三年底 | F2: 一一二年底
A3: 庫存現金 | C3: $ | D3: =BS!C3 -> 36210 | F3: $ | G3: =TB!C4 -> 36270
A4: 銀行存款 | D4: =SUM(BS!C4:C9) -> 5372373 | G4: =SUM(TB!C6:C11) -> 7552309
A5: 合 計 | C5: $ | D5: =SUM(D3:D4) -> 5408583 | F5: $ | G5: =G3+G4 -> 7588579
A6: (二)應收票據
C7: =C2 -> 一一三年底 | F7: =F2 -> 一一二年底
A8: 應收票據 | C8: $ | D8: =BS!C10 -> 4597726 | F8: $ | G8: =TB!C14 -> 3205259
A9: 合 計 | C9: $ | D9: =D8 -> 4597726 | F9: $ | G9: =G8 -> 3205259
A10: (三)應收帳款
C11: =C2 -> 一一三年底 | F11: =F2 -> 一一二年底
A12: 應收帳款 | C12: $ | D12: =BS!C11 -> 13444980 | F12: $ | G12: =TB!C16 -> 7243970
A13: 合 計 | C13: $ | D13: =SUM(D12:D12) -> 13444980 | F13: $ | G13: =G12 -> 7243970
A15: (四)其他應收帳款
C16: =C2 -> 一一三年底 | F16: =F2 -> 一一二年底
A17: 其他應收帳款 | C17: $ | D17: =BS!C12 -> 1028274 | F17: $ | G17: =TB!C22 -> 1197720
A18: 合 計 | C18: $ | D18: =SUM(D17:D17) -> 1028274 | F18: $ | G18: =G17 -> 1197720
A20: (五)存貨
C21: =C2 -> 一一三年底 | F21: =F2 -> 一一二年底
A22: 原料存貨 | C22: $ | D22: =BS!C13 -> 2961265 | F22: $ | G22: =TB!C27 -> 2450275
A23: 合計 | C23: $ | D23: =SUM(D22:D22) -> 2961265 | F23: $ | G23: =G22 -> 2450275
A26: (六)預付款項
C27: =C2 -> 一一三年底 | F27: =F2 -> 一一二年底
A28: 預付費用 | C28: $ | D28: =TB!I33 -> 395327 | F28: $ | G28: =TB!C33 -> 827848
A29: 留抵稅額 | D29: – | G29: =TB!C37 -> 509358
A30: 進項稅額 | D30: – | G30: =TB!C36 -> 16888
A31: 合 計 | C31: $ | D31: =D28 -> 395327 | F31: $ | G31: =G28+G30+G29 -> 1354094
A35: (八)無形資產
C36: =C2 -> 一一三年底 | F36: =F2 -> 一一二年底
A37: 無形資產 | C37: $ | D37: =TB!I79 -> 479288 | F37: $ | G37: =TB!C79 -> 303810
A38: 累計攤折 | D38: =-TB!J80 -> -234570 | G38: =-TB!D80 -> -183463
A39: 合計 | C39: $ | D39: =D37+D38 -> 244718 | F39: $ | G39: =G37+G38 -> 120347
A42: (九)存出保證金
C43: =C2 -> 一一三年底 | F43: =F2 -> 一一二年底
A44: 存出保證金 | C44: $ | D44: =BS!C35 -> 16825600 | F44: $ | G44: =TB!C100 -> 16825600
A45: 合 計 | C45: $ | D45: =SUM(D44:D44) -> 16825600 | F45: $ | G45: =G44 -> 16825600
A47: (十)預付設備款
C48: =C2 -> 一一三年底 | F48: =F2 -> 一一二年底
A49: 預付設備款 | C49: $ | D49: =BS!C36 -> 1596848 | F49: $ | G49: –
A50: 合 計 | C50: $ | D50: =D49 -> 1596848 | F50: $ | G50: =G49 -> –
...

Sheet 附註用人費用
B1: 功能別 | C1: 一一三年度 | F1: 一一二年度
C2: 屬於營業 | D2: 屬於營業 | E2: 合計 | F2: 屬於營業 | G2: 屬於營業 | H2: 合計
B3: 費用別 | C3: 成本者 | D3: 費用者 | F3: 成本者 | G3: 費用者
B4: 用人費用
B5: 薪資費用 | C5: =TB!I236+TB!I239 -> 7889677 | D5: =TB!I304 -> 9433488 | E5: =C5+D5 -> 17323165 | F5: 5519670 | G5: 7841710 | H5: =F5+G5 -> 13361380
B6: 勞健保費用 | C6: 852122 | D6: 650353 | E6: =C6+D6 -> 1502475 | F6: 676797 | G6: 767358 | H6: =F6+G6 -> 1444155
B7: 退休金費用 | C7: =TB!I262 -> 159998 | D7: =TB!I354 -> 353089 | E7: =C7+D7 -> 513087 | F7: 158598 | G7: 424485 | H7: =F7+G7 -> 583083
B8: 其他用人費用 | C8: =TB!I237+TB!I240 -> 1375269 | D8: =TB!I305 -> 676758 | E8: =C8+D8 -> 2052027 | F8: 753528 | G8: 735886 | H8: =F8+G8 -> 1489414
B9: 折舊費用 | C9: =TB!I252 -> 2945943 | D9: =TB!I320 -> 902651 | E9: =C9+D9 -> 3848594 | F9: 6463917 | G9: 1512255 | H9: =F9+G9 -> 7976172
B10: 攤銷費用 | C10: =TB!I253 -> 15876 | D10: =TB!I321 -> 35231 | E10: =D10 -> 35231 | F10: – | G10: 101268 | H10: =G10 -> 101268
B12: 加班費
B13: 伙食費
B20: 直接人工 | C20: =[2]當期損益表!C28 -> 18984961 | D20: =C20/E5 -> 1.0959291
B21: 製-伙 食 費 | C21: =[2]當期損益表!C37 -> 1162140
B22: 製-加班費 | C22: =[2]當期損益表!C41 -> 4015188
B23: 製-保 險 費 | C23: =[2]當期損益表!C34 -> 2287870
B24: 製-退職金 | C24: =[2]當期損益表!C42 -> 882411
B26: 薪資支出 | C26: =[2]當期損益表!C54 -> 14795026 | D26: =C26/E5 -> 0.85406021
B27: 保 險 費 | C27: =[2]當期損益表!C63 -> 1232742 | D27: =C27*D26 -> 1052835.9
B28: 伙 食 費 | C28: =[2]當期損益表!C68 -> 667200
B29: 加班費 | C29: =[2]當期損益表!C74 -> 1469201
B30: 退職金 | C30: =[2]當期損益表!C76 -> 316312 | D30: =C30*D26 -> 270149.49
C32: 成本 | D32: 費用
B33: 保險費
B34: 退職金

Sheet 附註不動產
C1: 土 地 | F1: 房屋及建築 | I1: 機器設備 | L1: 運輸設備 | O1: 辦公設備 | R1: 其他設備 | U1: 合 計
A2: 成 本
A3: 112年1月1日 | C3: $ | D3: 0 | F3: $ | G3: 9848566 | I3: $ | J3: 41821547 | L3: $ | M3: 6888571 | O3: $ | P3: 689337 | R3: $ | S3: 1546871 | U3: $ | V3: =SUM(D3:S3) -> 60794892
A4: 增 添 | G4: 1149762 | J4: 1667144 | M4: 1465730 | P4: 21989 | S4: 596200 | V4: =SUM(D4:S4) -> 4900825
A5: 重分類 | G5: 7314286 | J5: -7314286 | M5: - | P5: - | S5: - | V5: -
A6: 112年12月31日 | D6: 0 | G6: =SUM(G3:G5) -> 18312614 | J6: =SUM(J3:J5) -> 36174405 | M6: =SUM(M3:M5) -> 8354301 | P6: =SUM(P3:P5) -> 711326 | S6: =SUM(S3:S5) -> 2143071 | V6: =SUM(V3:V5) -> 65695717
A7: 增 添 | G7: - | J7: 1170000 | M7: 1044720 | P7: 103634 | S7: 69900 | V7: =SUM(D7:S7) -> 2388254
A8: 處 分 | G8: - | J8: - | M8: - | P8: - | S8: - | V8: -
A9: 113年12月31日 | C9: $ | D9: 0 | F9: $ | G9: =SUM(G6:G8) -> 18312614 | I9: $ | J9: =SUM(J6:J8) -> 37344405 | L9: $ | M9: =SUM(M6:M8) -> 9399021 | O9: $ | P9: =SUM(P6:P8) -> 814960 | R9: $ | S9: =SUM(S6:S8) -> 2212971 | V9: =SUM(V6:V8) -> 68083971
A10: 累計折舊
A11: 112年1月1日 | C11: $ | F11: $ | G11: 542287 | I11: $ | J11: 927671 | L11: $ | M11: 221048 | O11: $ | P11: 81594 | R11: $ | S11: 45888 | U11: $ | V11: =SUM(F11:U11) -> 1818488
A12: 折 舊 | G12: 2105404 | J12: 4125964 | M12: 1163497 | P12: 176936 | S12: 404371 | V12: =SUM(D12:S12) -> 7976172
A13: 重分類 | G13: 110822 | J13: -110822 | M13: - | P13: - | S13: - | V13: -
A14: 112年12月31日 | G14: =SUM(G11:G13) -> 2758513 | J14: =SUM(J11:J13) -> 4942813 | M14: =SUM(M11:M13) -> 1384545 | P14: =SUM(P11:P13) -> 258530 | S14: =SUM(S11:S13) -> 450259 | V14: =SUM(V11:V13) -> 9794660
A15: 折 舊 | G15: 940896 | J15: 1916250 | M15: 645945 | P15: 122398 | S15: 223105 | V15: =SUM(D15:S15) -> 3848594
A16: 處 分 | G16: - | J16: - | M16: - | P16: - | S16: - | V16: -
A17: 113年12月31日 | C17: $ | F17: $ | G17: =SUM(G14:G16) -> 3699409 | I17: $ | J17: =SUM(J14:J16) -> 6859063 | L17: $ | M17: =SUM(M14:M16) -> 2030490 | O17: $ | P17: =SUM(P14:P16) -> 380928 | R17: $ | S17: =SUM(S14:S16) -> 673364 | U17: $ | V17: =SUM(V14:V16) -> 13643254
A19: 帳面價值
A20: 113年12月31日 | C20: $ | D20: =D9-D17 -> 0 | F20: $ | G20: =G9-G17 -> 14613205 | I20: $ | J20: =J9-J17 -> 30485342 | L20: $ | M20: =M9-M17 -> 7368531 | O20: $ | P20: =P9-P17 -> 434032 | R20: $ | S20: =S9-S17 -> 1539607 | U20: $ | V20: =V9-V17 -> 54440717
A21: 112年1月1日 | C21: $ | D21: =D3-D11 -> 0 | F21: $ | G21: =G3-G11 -> 9306279 | I21: $ | J21: =J3-J11 -> 40893876 | L21: $ | M21: =M3-M11 -> 6667523 | O21: $ | P21: =P3-P11 -> 607743 | R21: $ | S21: =S3-S11 -> 1500983 | U21: $ | V21: =V3-V11 -> 58976404
A22: 112年12月31日 | C22: $ | D22: =D6-D14 -> 0 | F22: $ | G22: =G6-G14 -> 15554101 | I22: $ | J22: =J6-J14 -> 31231592 | L22: $ | M22: =M6-M14 -> 6969756 | O22: $ | P22: =P6-P14 -> 452796 | R22: $ | S22: =S6-S14 -> 1692812 | U22: $ | V22: =V6-V14 -> 55901057

Sheet TB
A1: 會計項目 | B1: 科項名稱 | C1: 期初借方 | D1: 期初貸方 | E1: 本期借方 | F1: 本期貸方 | G1: 本期借餘 | H1: 本期貸餘 | I1: 期末借餘 | J1: 期末貸餘
A2: 1000 | B2: 資產總額 | C2: 0 | D2: 0 | E2: 0 | F2: 0 | G2: 0 | H2: 0 | I2: 0 | J2: 0
A3: 1100 | B3: 流動資產 | C3: 0 | D3: 0 | E3: 0 | F3: 0 | G3: 0 | H3: 0 | I3: 0 | J3: 0
A4: 1111 | B4: 現金 | C4: 36270 | D4: 0 | E4: 738871 | F4: 738931 | G4: 0 | H4: 60 | I4: 36210 | J4: 0
A5: 1112 | B5: 銀行存款 | C5: 0 | D5: 0 | E5: 15 | F5: 15 | G5: 0 | H5: 0 | I5: 0 | J5: 0
A6: 1112-1 | B6: 銀行存款-合作金庫 | C6: 4171035 | D6: 0 | E6: 45709621 | F6: 47826998 | G6: 0 | H6: 2117377 | I6: 2053658 | J6: 0
A7: 1112-2 | B7: 定期存單-合作金庫 | C7: 4459 | D7: 0 | E7: 303776 | F7: 300000 | G7: 3776 | H7: 0 | I7: 8235 | J7: 0
A8: 1112-3 | B8: 銀行存款-彰銀活存 | C8: 3376184 | D8: 0 | E8: 48273859 | F8: 51558215 | G8: 0 | H8: 3284356 | I8: 91828 | J8: 0
A9: 1112-4 | B9: 銀行存款-彰銀支存 | C9: 0 | D9: 0 | E9: 5017388 | F9: 4856010 | G9: 161378 | H9: 0 | I9: 161378 | J9: 0
A10: 1112-5 | B10: 銀行存款-彰銀活存設質 | C10: 631 | D10: 0 | E10: 0 | F10: 0 | G10: 0 | H10: 0 | I10: 631 | J10: 0
A11: 1112-6 | B11: 銀行存款-土銀活存 | C11: 0 | D11: 0 | E11: 12076597 | F11: 9019954 | G11: 3056643 | H11: 0 | I11: 3056643 | J11: 0
A12: 1113 | B12: 約當現金 | C12: 0 | D12: 0 | E12: 0 | F12: 0 | G12: 0 | H12: 0 | I12: 0 | J12: 0
A13: 1114 | B13: 短期投資 | C13: 0 | D13: 0 | E13: 0 | F13: 0 | G13: 0 | H13: 0 | I13: 0 | J13: 0
... A386: 9999 | B386: 所得稅費用 | C386: 0 | D386: 0 | E386: 46762 | F386: 0 | G386: 46762 | H386: 0 | I386: 46762 | J386: 0

Sheet BS
A1: 資產項目 | B1: 資產項目名稱 | C1: 資產金額小計 | D1: 資產金額合計 | E1: 負債及淨值項目 | F1: 負債及淨值項目名稱 | G1: 負債及淨值金額小計 | H1: 負債及淨值金額合計
A2: 1100 | B2: 流動資產 | C2: 0 | D2: 28124966 | E2: 2100 | F2: 流動負債 | G2: 0 | H2: 22673269
A3: 1111 | B3: 現金 | C3: 36210 | D3: 0 | E3: 2110 | F3: 短期借款 | G3: 6701448 | H3: 0
A4: 1112-1 | B4: 銀行存款-合作金庫 | C4: 2053658 | D4: 0 | E4: 2112-1 | F4: 一年內到期長期借款 | G4: 6701448 | H4: 0
A5: 1112-2 | B5: 定期存單-合作金庫 | C5: 8235 | D5: 0 | E5: 2120 | F5: 應付票據 | G5: 311654 | H5: 0
A6: 1112-3 | B6: 銀行存款-彰銀活存 | C6: 91828 | D6: 0 | E6: 2121 | F6: 應付帳款 | G6: 4339539 | H6: 0
A7: 1112-4 | B7: 銀行存款-彰銀支存 | C7: 161378 | D7: 0 | E7: 2130 | F7: 其他應付款 | G7: 11112008 | H7: 0
A8: 1112-5 | B8: 銀行存款-彰銀活存設質 | C8: 631 | D8: 0 | E8: 2131 | F8: 應付費用 | G8: 7868422 | H8: 0
A9: 1112-6 | B9: 銀行存款-土銀活存 | C9: 3056643 | D9: 0 | E9: 2131-2 | F9: 應付薪資 | G9: 3012320 | H9: 0
A10: 1121 | B10: 應收票據 | C10: 4597726 | D10: 0 | E10: 2131-3 | F10: 應付利息 | G10: 15186 | H10: 0
A11: 1123 | B11: 應收帳款 | C11: 13444980 | D11: 0 | E11: 2132 | F11: 應付稅捐 | G11: 216080 | H11: 0
A12: 1129-3 | B12: 其他應收款 | C12: 1028274 | D12: 0 | E12: 2136 | F12: 預收款項 | G12: 1202 | H12: 0
A13: 1130 | B13: 存貨 | C13: 2961265 | D13: 0 | E13: 2137 | F13: 預收貨款 | G13: 1202 | H13: 0
... A18: 1191 | B18: 暫付款 | C18: 285908 | D18: 0 | E18: 2000 | F18: 負債總額 | G18: 0 | H18: 44274434
A19: 1199-1 | B19: 應退稅額 | C19: 2903 | D19: 0 | G19: 0 | H19: 0
A20: 1200 | B20: 非流動資產 | C20: 0 | D20: 77422803 | E20: 3100 | F20: 資本或股本(實收) | G20: 0 | H20: 90000000
A21: 1400 | B21: 固定資產 | C21: 54440717 | D21: 0 | E21: 3110 | F21: 股本(登記) | G21: 90000000 | H21: 0
A22: 1431 | B22: 房屋及建築 | C22: 18312614 | D22: 0 | E22: 3300 | F22: 資本公積 | G22: 0 | H22: 1400000
A23: 1432 | B23: 累計折舊-房屋及建築 | C23: -3699409 | D23: 0 | E23: 3400 | F23: 保留盈餘 | G23: 0 | H23: -30126665
A24: 1441 | B24: 機器設備 | C24: 37344405 | D24: 0 | E24: 3430 | F24: 累積盈虧 | G24: -30313711 | H24: 0
A25: 1442 | B25: 累計折舊-機器設備 | C25: -6859063 | D25: 0 | E25: 3432 | F25: 累積盈虧(87年以後) | G25: -30313711 | H25: 0
A26: 1451 | B26: 運輸設備 | C26: 9399021 | D26: 0 | E26: 3440 | F26: 本期損益 | G26: 187046 | H26: 0
A27: 1452 | B27: 累計折舊-運輸設備 | C27: -2030490 | D27: 0 | E27: 3000 | F27: 權益總額 | G27: 0 | H27: 61273335
A28: 1461 | B28: 辦公設備 | C28: 814960 | D28: 0 | G28: 0 | H28: 0
A29: 1462 | B29: 累計折舊-辦公設備 | C29: -380928 | D29: 0 | G29: 0 | H29: 0
A30: 1491 | B30: 其他固定資產 | C30: 2212971 | D30: 0 | G30: 0 | H30: 0
A31: 1492 | B31: 累計折舊-其他固定資產 | C31: -673364 | D31: 0 | G31: 0 | H31: 0
A32: 1510 | B32: 無形資產 | C32: 479288 | D32: 0 | G32: 0 | H32: 0
A33: 1511 | B33: 無形資產-累計攤折 | C33: -234570 | D33: 0 | G33: 0 | H33: 0
A34: 1900 | B34: 其他非流動資產 | C34: 22737368 | D34: 0 | G34: 0 | H34: 0
A35: 1901 | B35: 存出保證金 | C35: 16825600 | D35: 0 | G35: 0 | H35: 0
A36: 1903 | B36: 預付設備款 | C36: 1596848 | D36: 0 | G36: 0 | H36: 0
A37: 1904-1 | B37: 遞延所得稅資產 | C37: 4314920 | D37: 0 | G37: 0 | H37: 0
C38: 0 | D38: 0 | G38: 0 | H38: 0
A39: 1000 | B39: 資產總額 | C39: 0 | D39: 105547769 | E39: 9000 | F39: 負債及權益總額 | G39: 0 | H39: 105547769

Sheet IS
A1: 項目代號 | B1: 項目名稱 | C1: 小計金額 | D1: 合計金額 | E1: 百分比
A2: 4000 | B2: 營業收入淨額 | C2: 0 | D2: 52599315 | E2: 100
A3: 4100 | B3: 營業收入總額 | C3: 53353003 | D3: 0 | E3: 101.43
A4: 4101 | B4: 營業收入 | C4: 53353003 | D4: 0 | E4: 101.43
A5: 4202 | B5: 銷貨折讓 | C5: -753688 | D5: 0 | E5: -1.43
B6: 營業收入淨額 | C6: 0 | D6: 52599315 | E6: 100
A7: 5900 | B7: 營業成本 | C7: 0 | D7: 33039914 | E7: 62.81
A8: 5000 | B8: 進銷成本 | C8: 0 | D8: 0 | E8: 0
A9: 5100 | B9: 直接原料 | C9: 9063511 | D9: 0 | E9: 17.23
A10: 5110 | B10: 期初存料-原料 | C10: 2450275 | D10: 0 | E10: 4.65
A11: 5120 | B11: 本期進料-原料(淨額) | C11: 9574501 | D11: 0 | E11: 18.2
A12: 5121 | B12: 原料進料 | C12: 9574501 | D12: 0 | E12: 18.2
A13: 5130 | B13: 期末存貨-原料 | C13: -2961265 | D13: 0 | E13: -5.63
A14: 5300 | B14: 直接人工 | C14: 7014248 | D14: 0 | E14: 13.33
A15: 5301 | B15: 直接人工-免稅加班費 | C15: 1242398 | D15: 0 | E15: 2.36
A16: 5400 | B16: 製造費用**** | C16: 15719757 | D16: 0 | E16: 29.88
A17: 5401 | B17: 製-間接人工 | C17: 875429 | D17: 0 | E17: 1.66
A18: 5401-1 | B18: 製-間接人工(免稅加班費) | C18: 132871 | D18: 0 | E18: 0.25
... A41: 5570 | B41: 產銷成本 | C41: 33039914 | D41: 0 | E41: 62.81
B42: 營業毛利 | C42: 0 | D42: 19559401 | E42: 37.18
A43: 6000 | B43: 營業費用及損失總額 | C43: 0 | D43: 19136173 | E43: 36.38
A44: 6010 | B44: 薪資支出 | C44: 9433488 | D44: 0 | E44: 17.93
A45: 6010-1 | B45: 薪資支出(免稅加班費) | C45: 676758 | D45: 0 | E45: 1.28
A46: 6011 | B46: 租金支出 | C46: 1311571 | D46: 0 | E46: 2.49
A47: 6012 | B47: 文具用品 | C47: 69020 | D47: 0 | E47: 0.13
A48: 6013 | B48: 旅費 | C48: 37989 | D48: 0 | E48: 0.07
A49: 6014 | B49: 運費 | C49: 1527347 | D49: 0 | E49: 2.9
A50: 6015 | B50: 郵電費 | C50: 217644 | D50: 0 | E50: 0.41
A51: 6016 | B51: 修繕費 | C51: 568710 | D51: 0 | E51: 1.08
A52: 6017 | B52: 廣告費 | C52: 64257 | D52: 0 | E52: 0.12
A53: 6019 | B53: 保險費 | C53: 1105338 | D53: 0 | E53: 2.1
A54: 6020 | B54: 交際費 | C54: 25057 | D54: 0 | E54: 0.04
... A64: 603217 | B64: 參展費 | C64: 175184 | D64: 0 | E64: 0.33
B65: 營業淨利 | C65: 0 | D65: 423228 | E65: 0.8
A66: 7000 | B66: 非營業收入總額 | C66: 0 | D66: 514722 | E66: 0.97
A67: 7038 | B67: 利息收入 | C67: 160806 | D67: 0 | E67: 0.3
A68: 7044 | B68: 其他收入 | C68: 328916 | D68: 0 | E68: 0.62
A69: 7044-1 | B69: 出售下腳及廢料收入 | C69: 25000 | D69: 0 | E69: 0.04
A70: 8000 | B70: 非營業損失及費用總額 | C70: 0 | D70: 704142 | E70: 1.33
A71: 8046 | B71: 利息支出 | C71: 704142 | D71: 0 | E71: 1.33
...

Sheet VI-2資產
B1: 牛津會計師事務所
B2: 公司
B3: 商 業 會 計 項 目 表—資產
E4: (財簽適用)
B5: 三級 項目 | C5: 四級 項目 | D5: 會計項目名稱 | E5: 資產金額
E6: 105年 | F6: 104年 | G6: 103年 | H6: 增加(減少)數
H7: 105年度 | I7: 104年度
E8: (1) | F8: (2) | G8: (3) | H8: (2)-(1) | I8: (3)-(2) | J8: 篩選數字
D9: 資 產 | J9: =SUM(E9:I9) -> 0
D10: 流動資產 | J10: =SUM(E10:I10) -> 0
A11: 111現金及約當現金 | C11: 1111 | D11: 庫存現金 | E11: 1 | F11: 2 | G11: 3 | H11: =F11-E11 -> 1 | I11: =G11-F11 -> 1 | J11: =SUM(E11:I11) -> 8
A12: 111現金及約當現金 | C12: 1112 | D12: 零用金/週轉金 | E12: 1 | F12: 2 | G12: 3 | H12: =F12-E12 -> 1 | I12: =G12-F12 -> 1 | J12: =SUM(E12:I12) -> 8
A13: 111現金及約當現金 | C13: 1113 | D13: 銀行存款 | E13: 1 | F13: 2 | G13: 3 | H13: =F13-E13 -> 1 | I13: =G13-F13 -> 1 | J13: =SUM(E13:I13) -> 8
A14: 111現金及約當現金 | C14: 1114 | D14: 在途現金 | E14: 1 | F14: 2 | G14: 3 | H14: =F14-E14 -> 1 | I14: =G14-F14 -> 1 | J14: =SUM(E14:I14) -> 8
A15: 111現金及約當現金 | C15: 1115 | D15: 約當現金 | E15: 1 | F15: 2 | G15: 3 | H15: =F15-E15 -> 1 | I15: =G15-F15 -> 1 | J15: =SUM(E15:I15) -> 8
A16: 111現金及約當現金 | B16: 111 | D16: 現金及約當現金 | E16: =SUBTOTAL(9,E11:E15) -> 5 | F16: =SUBTOTAL(9,F11:F15) -> 10 | G16: =SUBTOTAL(9,G11:G15) -> 15 | H16: =SUBTOTAL(9,H11:H15) -> 5 | I16: =SUBTOTAL(9,I11:I15) -> 5 | J16: =SUM(E16:I16) -> 40
A17: 112透過損益按公允價值衡量之金融資產－流動 | C17: 1121 | D17: 透過損益按公允價值衡量之金融資產－流動 | H17: =F17-E17 -> 0 | I17: =G17-F17 -> 0 | J17: =SUM(E17:I17) -> 0
A18: 112透過損益按公允價值衡量之金融資產－流動 | C18: 1122 | D18: 透過損益按公允價值衡量之金融資產評價調整—流動 | H18: =F18-E18 -> 0 | I18: =G18-F18 -> 0 | J18: =SUM(E18:I18) -> 0
A19: 112透過損益按公允價值衡量之金融資產－流動 | B19: 112 | D19: 透過損益按公允價值衡量之金融資產－流動 | E19: =SUBTOTAL(9,E17:E18) -> 0 | F19: =SUBTOTAL(9,F17:F18) -> 0 | G19: =SUBTOTAL(9,G17:G18) -> 0 | H19: =SUBTOTAL(9,H17:H18) -> 0 | I19: =SUBTOTAL(9,I17:I18) -> 0 | J19: =SUM(E19:I19) -> 0
A20: 113備供出售金融資產－流動 | C20: 1131 | D20: 備供出售金融資產－流動 | H20: =F20-E20 -> 0 | I20: =G20-F20 -> 0 | J20: =SUM(E20:I20) -> 0
A21: 113備供出售金融資產－流動 | C21: 1132 | D21: 備供出售金融資產評價調整—流動 | H21: =F21-E21 -> 0 | I21: =G21-F21 -> 0 | J21: =SUM(E21:I21) -> 0
A22: 113備供出售金融資產－流動 | C22: 1133 | D22: 累計減損—備供出售金融資產—流動 | H22: =F22-E22 -> 0 | I22: =G22-F22 -> 0 | J22: =SUM(E22:I22) -> 0
A23: 113備供出售金融資產－流動 | B23: 113 | D23: 備供出售金融資產－流動 | E23: =SUBTOTAL(9,E20:E22) -> 0 | F23: =SUBTOTAL(9,F20:F22) -> 0 | G23: =SUBTOTAL(9,G20:G22) -> 0 | H23: =SUBTOTAL(9,H20:H22) -> 0 | I23: =SUBTOTAL(9,I20:I22) -> 0 | J23: =SUM(E23:I23) -> 0
A24: 114以成本衡量之金融資產－流動 | C24: 1141 | D24: 以成本衡量之金融資產－流動 | H24: =F24-E24 -> 0 | I24: =G24-F24 -> 0 | J24: =SUM(E24:I24) -> 0
A25: 114以成本衡量之金融資產－流動 | C25: 1142 | D25: 累計減損—以成本衡量之金融資產—流動 | H25: =F25-E25 -> 0 | I25: =G25-F25 -> 0 | J25: =SUM(E25:I25) -> 0
A26: 114以成本衡量之金融資產－流動 | B26: 114 | D26: 以成本衡量之金融資產－流動 | E26: =SUBTOTAL(9,E24:E25) -> 0 | F26: =SUBTOTAL(9,F24:F25) -> 0 | G26: =SUBTOTAL(9,G24:G25) -> 0 | H26: =SUBTOTAL(9,H24:H25) -> 0 | I26: =SUBTOTAL(9,I24:I25) -> 0 | J26: =SUM(E26:I26) -> 0
A27: 115無活絡市場之債務工具投資－流動 | C27: 1151 | D27: 無活絡市場之債務工具投資－流動 | H27: =F27-E27 -> 0 | I27: =G27-F27 -> 0 | J27: =SUM(E27:I27) -> 0
A28: 115無活絡市場之債務工具投資－流動 | C28: 1152 | D28: 累計減損—無活絡市場之債務工具投資—流動 | H28: =F28-E28 -> 0 | I28: =G28-F28 -> 0 | J28: =SUM(E28:I28) -> 0
A29: 115無活絡市場之債務工具投資－流動 | B29: 115 | D29: 無活絡市場之債務工具投資－流動 | E29: =SUBTOTAL(9,E27:E28) -> 0 | F29: =SUBTOTAL(9,F27:F28) -> 0 | G29: =SUBTOTAL(9,G27:G28) -> 0 | H29: =SUBTOTAL(9,H27:H28) -> 0 | I29: =SUBTOTAL(9,I27:I28) -> 0 | J29: =SUM(E29:I29) -> 0
A30: 116持有至到期日金融資產—流動 | C30: 1161 | D30: 持有至到期日金融資產—流動 | H30: =F30-E30 -> 0 | I30: =G30-F30 -> 0 | J30: =SUM(E30:I30) -> 0
A31: 116持有至到期日金融資產—流動 | C31: 1162 | D31: 累計減損—持有至到期日金融資產—流動 | H31: =F31-E31 -> 0 | I31: =G31-F31 -> 0 | J31: =SUM(E31:I31) -> 0
A32: 116持有至到期日金融資產—流動 | B32: 116 | D32: 持有至到期日金融資產—流動 | E32: =SUBTOTAL(9,E30:E31) -> 0 | F32: =SUBTOTAL(9,F30:F31) -> 0 | G32: =SUBTOTAL(9,G30:G31) -> 0 | H32: =SUBTOTAL(9,H30:H31) -> 0 | I32: =SUBTOTAL(9,I30:I31) -> 0 | J32: =SUM(E32:I32) -> 0
A33: 117避險之衍生金融資產－流動 | C33: 1171 | D33: 避險之衍生金融資產－流動 | H33: =F33-E33 -> 0 | I33: =G33-F33 -> 0 | J33: =SUM(E33:I33) -> 0
A34: 117避險之衍生金融資產－流動 | C34: 1172 | D34: 避險之衍生金融資產評價調整—流動 | H34: =F34-E34 -> 0 | I34: =G34-F34 -> 0 | J34: =SUM(E34:I34) -> 0
A35: 117避險之衍生金融資產－流動 | B35: 117 | D35: 避險之衍生金融資產－流動 | E35: =SUBTOTAL(9,E33:E34) -> 0 | F35: =SUBTOTAL(9,F33:F34) -> 0 | G35: =SUBTOTAL(9,G33:G34) -> 0 | H35: =SUBTOTAL(9,H33:H34) -> 0 | I35: =SUBTOTAL(9,I33:I34) -> 0 | J35: =SUM(E35:I35) -> 0
A36: 118應收票據淨額 | C36: 1181 | D36: 應收票據 | H36: =F36-E36 -> 0 | I36: =G36-F36 -> 0 | J36: =SUM(E36:I36) -> 0
A37: 118應收票據淨額 | C37: 1182 | D37: 應收票據貼現 | H37: =F37-E37 -> 0 | I37: =G37-F37 -> 0 | J37: =SUM(E37:I37) -> 0
A38: 118應收票據淨額 | C38: 1183 | D38: 應收票據—關係人 | H38: =F38-E38 -> 0 | I38: =G38-F38 -> 0 | J38: =SUM(E38:I38) -> 0
A39: 118應收票據淨額 | C39: 1184 | D39: 其他應收票據 | H39: =F39-E39 -> 0 | I39: =G39-F39 -> 0 | J39: =SUM(E39:I39) -> 0
A40: 118應收票據淨額 | C40: 1185 | D40: 備抵呆帳—應收票據 | H40: =F40-E40 -> 0 | I40: =G40-F40 -> 0 | J40: =SUM(E40:I40) -> 0
...

Sheet VI-2負債及權益
C1: 牛津會計師事務所
C2: 公司
C3: 商 業 會 計 項 目 表—負債及權益
C4: (財簽適用)
A5: 三級 項目 | B5: 三級 項目 | C5: 四級 項目 | D5: 會計項目名稱 | E5: 負債及權益金額
A6: 三級 項目 | E6: 105年 | F6: 104年 | G6: 103年 | H6: 增加(減少)數
H7: 105年度 | I7: 104年度
A8: 三級 項目 | E8: (1) | F8: (2) | G8: (3) | H8: (1)-(2) | I8: (2)-(3) | J8: 篩選數字
D9: 負債
D10: 流動負債
A11: 211短期借款 | C11: 2111 | D11: 銀行透支 | E11: 1 | F11: 2 | G11: 3 | H11: =E11-F11 -> -1 | I11: =F11-G11 -> -1 | J11: =SUM(E11:I11) -> 4
A12: 211短期借款 | C12: 2112 | D12: 銀行借款 | E12: 1 | F12: 2 | G12: 3 | H12: =E12-F12 -> -1 | I12: =F12-G12 -> -1 | J12: =SUM(E12:I12) -> 4
A13: 211短期借款 | C13: 2113 | D13: 短期借款—業主 | E13: 1 | F13: 2 | G13: 3 | H13: =E13-F13 -> -1 | I13: =F13-G13 -> -1 | J13: =SUM(E13:I13) -> 4
A14: 211短期借款 | C14: 2114 | D14: 短期借款—員工 | E14: 1 | F14: 2 | G14: 3 | H14: =E14-F14 -> -1 | I14: =F14-G14 -> -1 | J14: =SUM(E14:I14) -> 4
A15: 211短期借款 | C15: 2115 | D15: 短期借款—關係人 | E15: 1 | F15: 2 | G15: 3 | H15: =E15-F15 -> -1 | I15: =F15-G15 -> -1 | J15: =SUM(E15:I15) -> 4
A16: 211短期借款 | C16: 2116 | D16: 短期借款—其他 | E16: 1 | F16: 2 | G16: 3 | H16: =E16-F16 -> -1 | I16: =F16-G16 -> -1 | J16: =SUM(E16:I16) -> 4
A17: 211短期借款 | B17: 211 | D17: 短期借款 | E17: =SUBTOTAL(9,E11:E16) -> 6 | F17: =SUBTOTAL(9,F11:F16) -> 12 | G17: =SUBTOTAL(9,G11:G16) -> 18 | H17: =SUBTOTAL(9,H11:H16) -> -6 | I17: =SUBTOTAL(9,I11:I16) -> -6 | J17: =SUM(E17:I17) -> 24
A18: 212應付短期票券 | C18: 2121 | D18: 應付商業本票 | E18: 0 | F18: 0 | G18: 0 | H18: =E18-F18 -> 0 | I18: =F18-G18 -> 0 | J18: =SUM(E18:I18) -> 0
A19: 212應付短期票券 | C19: 2122 | D19: 銀行承兌匯票 | E19: 22 | F19: 0 | G19: 0 | H19: =E19-F19 -> 22 | I19: =F19-G19 -> 0 | J19: =SUM(E19:I19) -> 44
A20: 212應付短期票券 | C20: 2123 | D20: 其他應付短期票券 | E20: 0 | F20: 0 | G20: 0 | H20: =E20-F20 -> 0 | I20: =F20-G20 -> 0 | J20: =SUM(E20:I20) -> 0
A21: 212應付短期票券 | C21: 2124 | D21: 應付短期票券折價 | E21: 0 | F21: 0 | G21: 0 | H21: =E21-F21 -> 0 | I21: =F21-G21 -> 0 | J21: =SUM(E21:I21) -> 0
A22: 212應付短期票券 | B22: 212 | D22: 應付短期票券 | E22: =SUBTOTAL(9,E18:E21) -> 22 | F22: =SUBTOTAL(9,F18:F21) -> 0 | G22: =SUBTOTAL(9,G18:G21) -> 0 | H22: =SUBTOTAL(9,H18:H21) -> 22 | I22: =SUBTOTAL(9,I18:I21) -> 0 | J22: =SUM(E22:I22) -> 44
A23: 213透過損益按公允價值衡量之金融負債－流動 | C23: 2131 | D23: 透過損益按公允價值衡量之金融負債－流動 | E23: 0 | F23: 0 | G23: 0 | H23: =E23-F23 -> 0 | I23: =F23-G23 -> 0 | J23: =SUM(E23:I23) -> 0
A24: 213透過損益按公允價值衡量之金融負債－流動 | C24: 2132 | D24: 透過損益按公允價值衡量之金融負債評價調整—流動 | E24: 3333 | F24: 0 | G24: 0 | H24: =E24-F24 -> 3333 | I24: =F24-G24 -> 0 | J24: =SUM(E24:I24) -> 6666
A25: 213透過損益按公允價值衡量之金融負債－流動 | B25: 213 | D25: 透過損益按公允價值衡量之金融負債－流動 | E25: =SUBTOTAL(9,E23:E24) -> 3333 | F25: =SUBTOTAL(9,F23:F24) -> 0 | G25: =SUBTOTAL(9,G23:G24) -> 0 | H25: =SUBTOTAL(9,H23:H24) -> 3333 | I25: =SUBTOTAL(9,I23:I24) -> 0 | J25: =SUM(E25:I25) -> 6666
A26: 214避險之衍生金融負債—流動 | C26: 2141 | D26: 避險之衍生金融負債—流動 | E26: 0 | F26: 0 | G26: 0 | H26: =E26-F26 -> 0 | I26: =F26-G26 -> 0 | J26: =SUM(E26:I26) -> 0
A27: 214避險之衍生金融負債—流動 | C27: 2142 | D27: 避險之衍生金融負債評價調整—流動 | E27: 0 | F27: 0 | G27: 0 | H27: =E27-F27 -> 0 | I27: =F27-G27 -> 0 | J27: =SUM(E27:I27) -> 0
A28: 214避險之衍生金融負債—流動 | B28: 214 | D28: 避險之衍生金融負債—流動 | E28: =SUBTOTAL(9,E26:E27) -> 0 | F28: =SUBTOTAL(9,F26:F27) -> 0 | G28: =SUBTOTAL(9,G26:G27) -> 0 | H28: =SUBTOTAL(9,H26:H27) -> 0 | I28: =SUBTOTAL(9,I26:I27) -> 0 | J28: =SUM(E28:I28) -> 0
A29: 215以成本衡量之金融負債－流動 | C29: 2151 | D29: 以成本衡量之金融負債－流動 | E29: 0 | F29: 0 | G29: 0 | H29: =E29-F29 -> 0 | I29: =F29-G29 -> 0 | J29: =SUM(E29:I29) -> 0
A30: 215以成本衡量之金融負債－流動 | B30: 215 | D30: 以成本衡量之金融負債－流動 | E30: =SUBTOTAL(9,E29:E29) -> 0 | F30: =SUBTOTAL(9,F29:F29) -> 0 | G30: =SUBTOTAL(9,G29:G29) -> 0 | H30: =SUBTOTAL(9,H29:H29) -> 0 | I30: =SUBTOTAL(9,I29:I29) -> 0 | J30: =SUM(E30:I30) -> 0
A31: 216應付票據 | C31: 2161 | D31: 應付票據 | E31: 0 | F31: 0 | G31: 0 | H31: =E31-F31 -> 0 | I31: =F31-G31 -> 0 | J31: =SUM(E31:I31) -> 0
A32: 216應付票據 | C32: 2162 | D32: 應付票據—關係人 | E32: 0 | F32: 0 | G32: 0 | H32: =E32-F32 -> 0 | I32: =F32-G32 -> 0 | J32: =SUM(E32:I32) -> 0
A33: 216應付票據 | C33: 2163 | D33: 其他應付票據 | E33: 0 | F33: 0 | G33: 0 | H33: =E33-F33 -> 0 | I33: =F33-G33 -> 0 | J33: =SUM(E33:I33) -> 0
A34: 216應付票據 | B34: 216 | D34: 應付票據 | E34: =SUBTOTAL(9,E31:E33) -> 0 | F34: =SUBTOTAL(9,F31:F33) -> 0 | G34: =SUBTOTAL(9,G31:G33) -> 0 | H34: =SUBTOTAL(9,H31:H33) -> 0 | I34: =SUBTOTAL(9,I31:I33) -> 0 | J34: =SUM(E34:I34) -> 0
A35: 217應付帳款 | C35: 2171 | D35: 應付帳款 | E35: 0 | F35: 0 | G35: 0 | H35: =E35-F35 -> 0 | I35: =F35-G35 -> 0 | J35: =SUM(E35:I35) -> 0
A36: 217應付帳款 | C36: 2172 | D36: 應付租賃款—流動 | E36: 0 | F36: 0 | G36: 0 | H36: =E36-F36 -> 0 | I36: =F36-G36 -> 0 | J36: =SUM(E36:I36) -> 0
A37: 217應付帳款 | C37: 2173 | D37: 應付帳款—關係人 | E37: 0 | F37: 0 | G37: 0 | H37: =E37-F37 -> 0 | I37: =F37-G37 -> 0 | J37: =SUM(E37:I37) -> 0
A38: 217應付帳款 | B38: 217 | D38: 應付帳款 | E38: =SUBTOTAL(9,E35:E37) -> 0 | F38: =SUBTOTAL(9,F35:F37) -> 0 | G38: =SUBTOTAL(9,G35:G37) -> 0 | H38: =SUBTOTAL(9,H35:H37) -> 0 | I38: =SUBTOTAL(9,I35:I37) -> 0 | J38: =SUM(E38:I38) -> 0
A39: 218 應付建造合約款 | C39: 218 | D39: 應付建造合約款 | E39: 0 | F39: 0 | G39: 0 | H39: =E39-F39 -> 0 | I39: =F39-G39 -> 0 | J39: =SUM(E39:I39) -> 0
A40: 218應付建造合約款 | B40: 218 | D40: 應付建造合約款 | E40: =SUBTOTAL(9,E39) -> 0 | F40: =SUBTOTAL(9,F39) -> 0 | G40: =SUBTOTAL(9,G39) -> 0 | H40: =SUBTOTAL(9,H39) -> 0 | I40: =SUBTOTAL(9,I39) -> 0 | J40: =SUM(E40:I40) -> 0
...

Sheet 104
A1: 資 產 | E1: 負債及股東權益
A2: 流動資產 | E2: 流動負債
A3: 現 金(附註二及三) | B3: 151815693 | C3: 82230452 | D3: =C3-B3 -> -69585241 | E3: 短期借款(附註三及五) | F3: 173539562 | G3: 96436082 | H3: =F3-G3 -> 77103480
A4: 應收票據(附註二) | B4: 169428468 | C4: 265863605 | D4: =C4-B4 -> 96435137 | E4: 應付票據 | F4: 56169952 | G4: 173201636 | H4: =F4-G4 -> -117031684
A5: 應收帳款(附註二) | B5: 291114741 | C5: 364529240 | D5: =C5-B5 -> 73414499 | E5: 應付帳款 | F5: 24391813 | G5: 107020814 | H5: =F5-G5 -> -82629001
A6: 存 貨（附註二及三） | B6: 430305453 | C6: 428681929 | D6: =C6-B6 -> -1623524 | E6: 應付費用 | F6: 18608615 | G6: 23943919 | H6: =F6-G6 -> -5335304
A7: 預付款項 | B7: 3131465 | C7: 7013896 | D7: =C7-B7 -> 3882431 | E7: 應付所得稅(附註二及三) | F7: 9697468 | G7: 15156447 | H7: =F7-G7 -> -5458979
A8: 其他流動資產(附註五) | B8: 17767045 | C8: 7305927 | D8: =C8-B8 -> -10461118 | E8: 一年內到期之長期借款 | F8: 64660733 | G8: 33436447 | H8: =F8-G8 -> 31224286
A9: 流動資產合計 | B9: =SUM(B3:B8) -> 1063562865 | C9: =SUM(C3:C8) -> 1155625049 | D9: =C9-B9 -> 92062184 | E9: (附註三及五) | H9: =F9-G9 -> 0
D10: =C10-B10 -> 0 | E10: 預收款項 | F10: 1243844 | G10: 371510 | H10: =F10-G10 -> 872334
A11: 基金及投資(附註一、二及三) | D11: =C11-B11 -> 0 | E11: 遞延所得稅負債-流動(附註二及三) | F11: 258557 | G11: 1578922 | H11: =F11-G11 -> -1320365
A12: 採權益法之長期股權投資 | B12: 6752501 | C12: 6065643 | D12: =C12-B12 -> -686858 | E12: 其他流動負債 | F12: 1116703 | G12: 1328967 | H12: =F12-G12 -> -212264
D13: =C13-B13 -> 0 | E13: 流動負債合計 | F13: =SUM(F3:F12) -> 349687247 | G13: =SUM(G3:G12) -> 452474744 | H13: =F13-G13 -> -102787497
A14: 固定資產(附註二、三、四、五及六) | D14: =C14-B14 -> 0 | H14: =F14-G14 -> 0
A15: 成 本 | D15: =C15-B15 -> 0 | E15: 長期負債 | H15: =F15-G15 -> 0
A16: 土 地 | B16: 288310086 | C16: 288310086 | D16: =C16-B16 -> 0 | E16: 長期借款(附註三及五) | F16: 904465360 | G16: 797736642 | H16: =F16-G16 -> 106728718
A17: 房屋及建築 | B17: 55599774 | C17: 51411864 | D17: =C17-B17 -> -4187910 | H17: =F17-G17 -> 0
A18: 機器設備 | B18: 608133599 | C18: 467217879 | D18: =C18-B18 -> -140915720 | E18: 負債總計 | F18: =F13+F16 -> 1254152607 | G18: =G13+G16 -> 1250211386 | H18: =F18-G18 -> 3941221
A19: 運輸設備 | B19: 2086822 | C19: 1656822 | D19: =C19-B19 -> -430000 | H19: =F19-G19 -> 0
A20: 辦公設備 | B20: 22974040 | C20: 21722896 | D20: =C20-B20 -> -1251144 | H20: =F20-G20 -> 0
A21: 其他固定資產 | B21: 14442877 | C21: 13926463 | D21: =C21-B21 -> -516414 | H21: =F21-G21 -> 0
B22: =SUM(B16:B21) -> 991547198 | C22: =SUM(C16:C21) -> 844246010 | D22: =C22-B22 -> -147301188 | E22: 股東權益 | H22: =F22-G22 -> 0
A23: 減：累計折舊 | B23: 221642030 | C23: 168259127 | D23: =C23-B23 -> -53382903 | E23: 股 本(附註一及三) | F23: 304980000 | G23: 304980000 | H23: =F23-G23 -> 0
A24: 未完工程及待驗設備 | B24: 3219825 | C24: 0 | D24: =C24-B24 -> -3219825 | E24: 資本公積(附註三) | F24: 57460000 | G24: 57460000 | H24: =F24-G24 -> 0
A25: 預付設備款 | B25: 6473 | C25: 6039 | D25: =C25-B25 -> -434 | E25: 保留盈餘(附註三) | H25: =F25-G25 -> 0
A26: 固定資產淨額 | B26: =B22-B23+B24+B25 -> 773131466 | C26: =C22-C23+C25 -> 675992922 | D26: =C26-B26 -> -97138544 | E26: 法定盈餘公積 | F26: =2656286+37016938 -> 39673224 | G26: =2656286+25862198 -> 28518484 | H26: =F26-G26 -> 11154740
D27: =C27-B27 -> 0 | E27: 未分配盈餘 | F27: =10906569+122890325+70518488 -> 204315382 | G27: =10906569+83470175+111547401 -> 205924145 | H27: =F27-G27 -> -1608763
A28: 其他非流動資產 | D28: =C28-B28 -> 0 | E28: 股東權益總計 | F28: =SUM(F23:F27) -> 606428606 | G28: =SUM(G23:G27) -> 596882629 | H28: =F28-G28 -> 9545977
A29: 存出保證金(附註五) | B29: 9882662 | C29: 4254001 | D29: =C29-B29 -> -5628661 | H29: =F29-G29 -> 0
A30: 未攤銷費用(附註二) | B30: 7251719 | C30: 5156400 | D30: =C30-B30 -> -2095319 | H30: =F30-G30 -> 0
A31: 其他資產合計 | B31: =SUM(B29:B30) -> 17134381 | C31: =SUM(C29:C30) -> 9410401 | D31: =C31-B31 -> -7723980 | H31: =F31-G31 -> 0
D32: =C32-B32 -> 0 | H32: =F32-G32 -> 0
A33: 資 產 總 計 | B33: =B9+B12+B26+B31 -> 1860581213 | C33: =C9+C12+C26+C31 -> 1847094015 | E33: 負債及股東權益總計 | F33: =F18+F28 -> 1860581213 | G33: =G18+G28 -> 1847094015
A37: 負 責 人：
B38: 288310086 | C38: － | D38: ) | E38: $ | F38: 288310086
B39: 55599774 | C39: 23598255 | D39: ) | F39: =B39-C39 -> 32001519
B40: 608133599 | C40: 172357639 | D40: ) | F40: =B40-C40 -> 435775960
B41: 2086822 | C41: 1243704 | D41: ) | F41: =B41-C41 -> 843118
B42: 22974040 | C42: 13576662 | D42: ) | F42: =B42-C42 -> 9397378
B43: 14442877 | C43: 10865770 | D43: ) | F43: =B43-C43 -> 3577107
...

Sheet 首次企業項目差異
A1: 本公司係依循企業會計準則公報第二號第二十二第二項之作法轉換至企業會計準則公報，因此揭露與先前適用之一般公認會計原則間之重大差異如下:
A2: 民國一○四年十二月三十一日資產負債表項目之調節表
A4: 先前一般公認會計原則 | E4: 轉換之影響 | G4: 企業會計準則公報
A5: 項目 | C5: 金額 | E5: 表達差異 | G5: 金額 | I5: 項目 | K5: 註
A6: 流動資產 | I6: 流動資產
A7: 現金及約當現金 | I7: 現金及約當現金 | K7: 1
A8: 公平價值變動列入損益之金融資產-流動 | I8: 透過損益按公允價值衡量之金融資產-流動 | K8: 2
A9: 備供出售金融資產-流動 | I9: 備供出售金融資產-流動
A10: 持有至到期日金融資產-流動 | I10: 持有至到期日金融資產-流動
A11: 避險之衍生性金融資產-流動 | I11: 避險之衍生金融資產-流動
A12: 以成本衡量之金融資產-流動 | I12: 以成本衡量之金融資產-流動 | K12: 2
A13: 無活絡市場之債券投資-流動 | I13: 無活絡市場之債券投資-流動 | K13: 1
A14: 應收票據 | I14: 應收票據
A15: 應收帳款 | I15: 應收帳款
A16: 其他應收款 | I16: 其他應收款
A17: - | I17: 當期所得稅資產
A18: 存貨 | I18: 存貨
A19: - | I19: 生物資產-流動
A20: 在建工程 | I20: 在建工程
A21: 預付款項 | I21: 預付款項 | K21: 3,5
A22: 遞延所得稅資產 | I22: - | K22: 7
A23: 待出售非流動資產 | I23: 待出售非流動資產
A24: 其他流動資產 | I24: 其他流動資產
A25: 流動資產合計 | I25: 流動資產合計
A27: 基金及投資 | I27: 非流動資產
A28: 公平價值變動列入損益之金融資產-非流動 | I28: 透過損益按公允價值衡量之金融資產-非流動
A29: 備供出售金融資產-非流動 | I29: 備供出售金融資產-非流動 | K29: 2
A30: 持有至到期日金融資產-非流動 | I30: 持有至到期日金融資產-非流動
A31: 避險之衍生性金融資產-非流動 | I31: 避險之衍生金融資產-非流動
A32: 以成本衡量之金融資產-非流動 | I32: 以成本衡量之金融資產-非流動 | K32: 2
A33: 無活絡市場之債券投資-非流動 | I33: 無活絡市場之債券投資-非流動
A34: 償債基金 | I34: 償債基金
A35: 採權益法之長期股權投資 | I35: 採權益法之投資
A36: 其他金融資產 | I36: 其他金融資產
A39: 固定資產淨額 | I39: 不動產、廠房及設備 | K39: 5
A40: - | I40: 投資性不動產 | K40: 4
A42: 無形資產合計 | I42: 無形資產 | K42: 3
A43: - | I43: 生物資產-非流動
I45: 預付設備款
A47: 其他資產
...
